Workbook

Sheet Instructions
A1: MIT Flyer Coverage Tracker
A3: How to use:
A5: 1. Go to 'Coverage Data' to enter posting data. One row = one posting spot.
A6: 2. Columns: Building, Bldg #, Floor, Spot Name, Spot Type, Assigned To, Posted (YES/NO), Date, Notes.
A7: 3. 'Summary' auto-calculates coverage by building.
A8: 4. Update the 'Spot Name' column with real spot descriptions (e.g. 'Main Lobby Board').
A9: 5. Update the Posted column and Date after each flyering run.
A10: 6. To publish: File > Share > Publish to web > select 'Coverage Data' > CSV.
A12: This tracker covers 60 buildings and 287 spots.

Sheet Coverage Data
A1: Building | B1: Bldg # | C1: Floor | D1: Spot Name | E1: Spot Type | F1: Assigned To | G1: Posted | H1: Date Posted | I1: Notes
A2: Bldg 1 – Civil & Environmental Eng | B2: 1 | C2: 1 | D2: Floor 1 Board | E2: Bulletin Board | F2: Priya | G2: NO
A3: Bldg 1 – Civil & Environmental Eng | B3: 1 | C3: 2 | D3: Floor 2 Board | E3: Bulletin Board | F3: Priya | G3: NO
A4: Bldg 1 – Civil & Environmental Eng | B4: 1 | C4: 3 | D4: Floor 3 Board | E4: Bulletin Board | F4: Priya | G4: YES | H4: 2026-03-10
A5: Bldg 1 – Civil & Environmental Eng | B5: 1 | C5: 4 | D5: Floor 4 Board | E5: Bulletin Board | F5: Priya | G5: NO | I5: Couldn't access
A6: Bldg 2 – Mechanical Eng | B6: 2 | C6: 1 | D6: Floor 1 Board | E6: Bulletin Board | F6: Marcus | G6: NO | I6: Need permission
A7: Bldg 2 – Mechanical Eng | B7: 2 | C7: 2 | D7: Floor 2 Board | E7: Bulletin Board | F7: Marcus | G7: YES | H7: 2026-03-10
A8: Bldg 2 – Mechanical Eng | B8: 2 | C8: 3 | D8: Floor 3 Board | E8: Bulletin Board | F8: Marcus | G8: YES | H8: 2026-03-10
A9: Bldg 2 – Mechanical Eng | B9: 2 | C9: 4 | D9: Floor 4 Board | E9: Bulletin Board | F9: Marcus | G9: YES | H9: 2026-03-10
A10: Bldg 3 – Maclaurin (West) | B10: 3 | C10: 1 | D10: Floor 1 Board | E10: Bulletin Board | F10: Elena | G10: YES | H10: 2026-03-10
A11: Bldg 3 – Maclaurin (West) | B11: 3 | C11: 2 | D11: Floor 2 Board | E11: Bulletin Board | F11: Elena | G11: YES | H11: 2026-03-10
A12: Bldg 3 – Maclaurin (West) | B12: 3 | C12: 3 | D12: Floor 3 Board | E12: Bulletin Board | F12: Elena | G12: YES | H12: 2026-03-10
A13: Bldg 3 – Maclaurin (West) | B13: 3 | C13: 4 | D13: Floor 4 Board | E13: Bulletin Board | F13: Elena | G13: YES | H13: 2026-03-10
A14: Bldg 4 – Maclaurin (East) | B14: 4 | C14: 1 | D14: Floor 1 Board | E14: Bulletin Board | F14: DeShawn | G14: NO | I14: Need permission
A15: Bldg 4 – Maclaurin (East) | B15: 4 | C15: 2 | D15: Floor 2 Board | E15: Bulletin Board | F15: DeShawn | G15: YES | H15: 2026-03-10
A16: Bldg 4 – Maclaurin (East) | B16: 4 | C16: 3 | D16: Floor 3 Board | E16: Bulletin Board | F16: DeShawn | G16: YES | H16: 2026-03-10
A17: Bldg 4 – Maclaurin (East) | B17: 4 | C17: 4 | D17: Floor 4 Board | E17: Bulletin Board | F17: DeShawn | G17: YES | H17: 2026-03-10
A18: Bldg 5 – Chemistry | B18: 5 | C18: 1 | D18: Floor 1 Board | E18: Bulletin Board | F18: Lina | G18: NO
A19: Bldg 5 – Chemistry | B19: 5 | C19: 2 | D19: Floor 2 Board | E19: Bulletin Board | F19: Lina | G19: NO | I19: Couldn't access
A20: Bldg 5 – Chemistry | B20: 5 | C20: 3 | D20: Floor 3 Board | E20: Bulletin Board | F20: Lina | G20: YES | H20: 2026-03-10
A21: Bldg 5 – Chemistry | B21: 5 | C21: 4 | D21: Floor 4 Board | E21: Bulletin Board | F21: Lina | G21: YES | H21: 2026-03-10
A22: Bldg 6 – Electrical Eng | B22: 6 | C22: 1 | D22: Floor 1 Board | E22: Bulletin Board | F22: Jordan | G22: YES | H22: 2026-03-10
A23: Bldg 6 – Electrical Eng | B23: 6 | C23: 2 | D23: Floor 2 Board | E23: Bulletin Board | F23: Jordan | G23: NO
A24: Bldg 6 – Electrical Eng | B24: 6 | C24: 3 | D24: Floor 3 Board | E24: Bulletin Board | F24: Jordan | G24: YES | H24: 2026-03-10
A25: Bldg 6 – Electrical Eng | B25: 6 | C25: 4 | D25: Floor 4 Board | E25: Bulletin Board | F25: Jordan | G25: YES | H25: 2026-03-10
A26: Bldg 7 – Rogers Building | B26: 7 | C26: 1 | D26: Floor 1 Board | E26: Bulletin Board | F26: Priya | G26: NO | I26: Need permission
A27: Bldg 7 – Rogers Building | B27: 7 | C27: 2 | D27: Floor 2 Board | E27: Bulletin Board | F27: Priya | G27: YES | H27: 2026-03-10
A28: Bldg 7 – Rogers Building | B28: 7 | C28: 3 | D28: Floor 3 Board | E28: Bulletin Board | F28: Priya | G28: YES | H28: 2026-03-10
A29: Bldg 7 – Rogers Building | B29: 7 | C29: 4 | D29: Floor 4 Board | E29: Bulletin Board | F29: Priya | G29: YES | H29: 2026-03-10
A30: Bldg 8 – Carr Lab | B30: 8 | C30: 1 | D30: Floor 1 Board | E30: Bulletin Board | F30: Marcus | G30: YES | H30: 2026-03-10
A31: Bldg 8 – Carr Lab | B31: 8 | C31: 2 | D31: Floor 2 Board | E31: Bulletin Board | F31: Marcus | G31: NO
A32: Bldg 8 – Carr Lab | B32: 8 | C32: 3 | D32: Floor 3 Board | E32: Bulletin Board | F32: Marcus | G32: YES | H32: 2026-03-10
A33: Bldg 8 – Carr Lab | B33: 8 | C33: 4 | D33: Floor 4 Board | E33: Bulletin Board | F33: Marcus | G33: NO | I33: Need permission
A34: Bldg 10 – Maclaurin (Great Dome) | B34: 10 | C34: 1 | D34: Floor 1 Board | E34: Bulletin Board | F34: Elena | G34: NO
A35: Bldg 10 – Maclaurin (Great Dome) | B35: 10 | C35: 2 | D35: Floor 2 Board | E35: Bulletin Board | F35: Elena | G35: YES | H35: 2026-03-10
A36: Bldg 10 – Maclaurin (Great Dome) | B36: 10 | C36: 3 | D36: Floor 3 Board | E36: Bulletin Board | F36: Elena | G36: NO
A37: Bldg 10 – Maclaurin (Great Dome) | B37: 10 | C37: 4 | D37: Floor 4 Board | E37: Bulletin Board | F37: Elena | G37: NO
A38: Bldg 9 – Hayden Library Annex | B38: 9 | C38: 1 | D38: Floor 1 Board | E38: Bulletin Board | F38: DeShawn | G38: YES | H38: 2026-03-10
A39: Bldg 9 – Hayden Library Annex | B39: 9 | C39: 2 | D39: Floor 2 Board | E39: Bulletin Board | F39: DeShawn | G39: YES | H39: 2026-03-10
A40: Bldg 9 – Hayden Library Annex | B40: 9 | C40: 3 | D40: Floor 3 Board | E40: Bulletin Board | F40: DeShawn | G40: YES | H40: 2026-03-10
...

Sheet Summary
A1: Building | B1: Total Spots | C1: Posted | D1: Not Posted | E1: Coverage %
A2: Bldg 1 – Civil & Environmental Eng | B2: =COUNTIF('Coverage Data'!A2:A288,A2) -> 4 | C2: =COUNTIFS('Coverage Data'!A2:A288,A2,'Coverage Data'!G2:G288,"YES") -> 1 | D2: =B2-C2 -> 3 | E2: =IF(B2>0,C2/B2,0) -> 0.25
A3: Bldg 10 – Maclaurin (Great Dome) | B3: =COUNTIF('Coverage Data'!A2:A288,A3) -> 4 | C3: =COUNTIFS('Coverage Data'!A2:A288,A3,'Coverage Data'!G2:G288,"YES") -> 1 | D3: =B3-C3 -> 3 | E3: =IF(B3>0,C3/B3,0) -> 0.25
A4: Bldg 11 – Homberg | B4: =COUNTIF('Coverage Data'!A2:A288,A4) -> 3 | C4: =COUNTIFS('Coverage Data'!A2:A288,A4,'Coverage Data'!G2:G288,"YES") -> 2 | D4: =B4-C4 -> 1 | E4: =IF(B4>0,C4/B4,0) -> 0.66666667
A5: Bldg 13 – Bush Building | B5: =COUNTIF('Coverage Data'!A2:A288,A5) -> 4 | C5: =COUNTIFS('Coverage Data'!A2:A288,A5,'Coverage Data'!G2:G288,"YES") -> 2 | D5: =B5-C5 -> 2 | E5: =IF(B5>0,C5/B5,0) -> 0.5
A6: Bldg 14 – Hayden Library | B6: =COUNTIF('Coverage Data'!A2:A288,A6) -> 4 | C6: =COUNTIFS('Coverage Data'!A2:A288,A6,'Coverage Data'!G2:G288,"YES") -> 2 | D6: =B6-C6 -> 2 | E6: =IF(B6>0,C6/B6,0) -> 0.5
A7: Bldg 16 – Dorrance (MatSci) | B7: =COUNTIF('Coverage Data'!A2:A288,A7) -> 4 | C7: =COUNTIFS('Coverage Data'!A2:A288,A7,'Coverage Data'!G2:G288,"YES") -> 2 | D7: =B7-C7 -> 2 | E7: =IF(B7>0,C7/B7,0) -> 0.5
A8: Bldg 18 – Dreyfus (Chemistry) | B8: =COUNTIF('Coverage Data'!A2:A288,A8) -> 4 | C8: =COUNTIFS('Coverage Data'!A2:A288,A8,'Coverage Data'!G2:G288,"YES") -> 3 | D8: =B8-C8 -> 1 | E8: =IF(B8>0,C8/B8,0) -> 0.75
A9: Bldg 2 – Mechanical Eng | B9: =COUNTIF('Coverage Data'!A2:A288,A9) -> 4 | C9: =COUNTIFS('Coverage Data'!A2:A288,A9,'Coverage Data'!G2:G288,"YES") -> 3 | D9: =B9-C9 -> 1 | E9: =IF(B9>0,C9/B9,0) -> 0.75
A10: Bldg 24 – Nuclear Sci & Eng | B10: =COUNTIF('Coverage Data'!A2:A288,A10) -> 5 | C10: =COUNTIFS('Coverage Data'!A2:A288,A10,'Coverage Data'!G2:G288,"YES") -> 3 | D10: =B10-C10 -> 2 | E10: =IF(B10>0,C10/B10,0) -> 0.6
A11: Bldg 26 – Compton Labs | B11: =COUNTIF('Coverage Data'!A2:A288,A11) -> 5 | C11: =COUNTIFS('Coverage Data'!A2:A288,A11,'Coverage Data'!G2:G288,"YES") -> 4 | D11: =B11-C11 -> 1 | E11: =IF(B11>0,C11/B11,0) -> 0.8
A12: Bldg 3 – Maclaurin (West) | B12: =COUNTIF('Coverage Data'!A2:A288,A12) -> 4 | C12: =COUNTIFS('Coverage Data'!A2:A288,A12,'Coverage Data'!G2:G288,"YES") -> 4 | D12: =B12-C12 -> 0 | E12: =IF(B12>0,C12/B12,0) -> 1
A13: Bldg 31 – Sloan Labs (Aero/Astro) | B13: =COUNTIF('Coverage Data'!A2:A288,A13) -> 3 | C13: =COUNTIFS('Coverage Data'!A2:A288,A13,'Coverage Data'!G2:G288,"YES") -> 2 | D13: =B13-C13 -> 1 | E13: =IF(B13>0,C13/B13,0) -> 0.66666667
A14: Bldg 32 – Stata Center (CSAIL) | B14: =COUNTIF('Coverage Data'!A2:A288,A14) -> 9 | C14: =COUNTIFS('Coverage Data'!A2:A288,A14,'Coverage Data'!G2:G288,"YES") -> 5 | D14: =B14-C14 -> 4 | E14: =IF(B14>0,C14/B14,0) -> 0.55555556
A15: Bldg 33 – Guggenheim (Aero) | B15: =COUNTIF('Coverage Data'!A2:A288,A15) -> 4 | C15: =COUNTIFS('Coverage Data'!A2:A288,A15,'Coverage Data'!G2:G288,"YES") -> 3 | D15: =B15-C15 -> 1 | E15: =IF(B15>0,C15/B15,0) -> 0.75
A16: Bldg 34 – EG&G Education Center | B16: =COUNTIF('Coverage Data'!A2:A288,A16) -> 4 | C16: =COUNTIFS('Coverage Data'!A2:A288,A16,'Coverage Data'!G2:G288,"YES") -> 2 | D16: =B16-C16 -> 2 | E16: =IF(B16>0,C16/B16,0) -> 0.5
A17: Bldg 35 – Sloan Automotive Lab | B17: =COUNTIF('Coverage Data'!A2:A288,A17) -> 3 | C17: =COUNTIFS('Coverage Data'!A2:A288,A17,'Coverage Data'!G2:G288,"YES") -> 2 | D17: =B17-C17 -> 1 | E17: =IF(B17>0,C17/B17,0) -> 0.66666667
A18: Bldg 36 – Fairchild | B18: =COUNTIF('Coverage Data'!A2:A288,A18) -> 4 | C18: =COUNTIFS('Coverage Data'!A2:A288,A18,'Coverage Data'!G2:G288,"YES") -> 2 | D18: =B18-C18 -> 2 | E18: =IF(B18>0,C18/B18,0) -> 0.5
A19: Bldg 37 – McNair Building | B19: =COUNTIF('Coverage Data'!A2:A288,A19) -> 4 | C19: =COUNTIFS('Coverage Data'!A2:A288,A19,'Coverage Data'!G2:G288,"YES") -> 2 | D19: =B19-C19 -> 2 | E19: =IF(B19>0,C19/B19,0) -> 0.5
A20: Bldg 38 – Fairchild Annex | B20: =COUNTIF('Coverage Data'!A2:A288,A20) -> 4 | C20: =COUNTIFS('Coverage Data'!A2:A288,A20,'Coverage Data'!G2:G288,"YES") -> 3 | D20: =B20-C20 -> 1 | E20: =IF(B20>0,C20/B20,0) -> 0.75
A21: Bldg 39 – Brown Building | B21: =COUNTIF('Coverage Data'!A2:A288,A21) -> 3 | C21: =COUNTIFS('Coverage Data'!A2:A288,A21,'Coverage Data'!G2:G288,"YES") -> 2 | D21: =B21-C21 -> 1 | E21: =IF(B21>0,C21/B21,0) -> 0.66666667
A22: Bldg 4 – Maclaurin (East) | B22: =COUNTIF('Coverage Data'!A2:A288,A22) -> 4 | C22: =COUNTIFS('Coverage Data'!A2:A288,A22,'Coverage Data'!G2:G288,"YES") -> 3 | D22: =B22-C22 -> 1 | E22: =IF(B22>0,C22/B22,0) -> 0.75
A23: Bldg 45 – Schwarzman Computing | B23: =COUNTIF('Coverage Data'!A2:A288,A23) -> 5 | C23: =COUNTIFS('Coverage Data'!A2:A288,A23,'Coverage Data'!G2:G288,"YES") -> 3 | D23: =B23-C23 -> 2 | E23: =IF(B23>0,C23/B23,0) -> 0.6
A24: Bldg 46 – Brain & Cognitive Sci | B24: =COUNTIF('Coverage Data'!A2:A288,A24) -> 6 | C24: =COUNTIFS('Coverage Data'!A2:A288,A24,'Coverage Data'!G2:G288,"YES") -> 3 | D24: =B24-C24 -> 3 | E24: =IF(B24>0,C24/B24,0) -> 0.5
A25: Bldg 5 – Chemistry | B25: =COUNTIF('Coverage Data'!A2:A288,A25) -> 4 | C25: =COUNTIFS('Coverage Data'!A2:A288,A25,'Coverage Data'!G2:G288,"YES") -> 2 | D25: =B25-C25 -> 2 | E25: =IF(B25>0,C25/B25,0) -> 0.5
A26: Bldg 50 – Walker Memorial | B26: =COUNTIF('Coverage Data'!A2:A288,A26) -> 3 | C26: =COUNTIFS('Coverage Data'!A2:A288,A26,'Coverage Data'!G2:G288,"YES") -> 3 | D26: =B26-C26 -> 0 | E26: =IF(B26>0,C26/B26,0) -> 1
A27: Bldg 54 – Green Building (Earth Sci) | B27: =COUNTIF('Coverage Data'!A2:A288,A27) -> 18 | C27: =COUNTIFS('Coverage Data'!A2:A288,A27,'Coverage Data'!G2:G288,"YES") -> 12 | D27: =B27-C27 -> 6 | E27: =IF(B27>0,C27/B27,0) -> 0.66666667
A28: Bldg 56 – Whitaker (BioEng) | B28: =COUNTIF('Coverage Data'!A2:A288,A28) -> 5 | C28: =COUNTIFS('Coverage Data'!A2:A288,A28,'Coverage Data'!G2:G288,"YES") -> 4 | D28: =B28-C28 -> 1 | E28: =IF(B28>0,C28/B28,0) -> 0.8
A29: Bldg 6 – Electrical Eng | B29: =COUNTIF('Coverage Data'!A2:A288,A29) -> 4 | C29: =COUNTIFS('Coverage Data'!A2:A288,A29,'Coverage Data'!G2:G288,"YES") -> 3 | D29: =B29-C29 -> 1 | E29: =IF(B29>0,C29/B29,0) -> 0.75
A30: Bldg 62 – East Campus (West Parallel) | B30: =COUNTIF('Coverage Data'!A2:A288,A30) -> 5 | C30: =COUNTIFS('Coverage Data'!A2:A288,A30,'Coverage Data'!G2:G288,"YES") -> 2 | D30: =B30-C30 -> 3 | E30: =IF(B30>0,C30/B30,0) -> 0.4
A31: Bldg 64 – East Campus (East Parallel) | B31: =COUNTIF('Coverage Data'!A2:A288,A31) -> 5 | C31: =COUNTIFS('Coverage Data'!A2:A288,A31,'Coverage Data'!G2:G288,"YES") -> 2 | D31: =B31-C31 -> 3 | E31: =IF(B31>0,C31/B31,0) -> 0.4
A32: Bldg 66 – Landau (ChemE) | B32: =COUNTIF('Coverage Data'!A2:A288,A32) -> 5 | C32: =COUNTIFS('Coverage Data'!A2:A288,A32,'Coverage Data'!G2:G288,"YES") -> 5 | D32: =B32-C32 -> 0 | E32: =IF(B32>0,C32/B32,0) -> 1
A33: Bldg 68 – Koch Biology | B33: =COUNTIF('Coverage Data'!A2:A288,A33) -> 6 | C33: =COUNTIFS('Coverage Data'!A2:A288,A33,'Coverage Data'!G2:G288,"YES") -> 5 | D33: =B33-C33 -> 1 | E33: =IF(B33>0,C33/B33,0) -> 0.83333333
A34: Bldg 7 – Rogers Building | B34: =COUNTIF('Coverage Data'!A2:A288,A34) -> 4 | C34: =COUNTIFS('Coverage Data'!A2:A288,A34,'Coverage Data'!G2:G288,"YES") -> 3 | D34: =B34-C34 -> 1 | E34: =IF(B34>0,C34/B34,0) -> 0.75
A35: Bldg 76 – Koch Institute | B35: =COUNTIF('Coverage Data'!A2:A288,A35) -> 7 | C35: =COUNTIFS('Coverage Data'!A2:A288,A35,'Coverage Data'!G2:G288,"YES") -> 4 | D35: =B35-C35 -> 3 | E35: =IF(B35>0,C35/B35,0) -> 0.57142857
A36: Bldg 8 – Carr Lab | B36: =COUNTIF('Coverage Data'!A2:A288,A36) -> 4 | C36: =COUNTIFS('Coverage Data'!A2:A288,A36,'Coverage Data'!G2:G288,"YES") -> 2 | D36: =B36-C36 -> 2 | E36: =IF(B36>0,C36/B36,0) -> 0.5
A37: Bldg 9 – Hayden Library Annex | B37: =COUNTIF('Coverage Data'!A2:A288,A37) -> 3 | C37: =COUNTIFS('Coverage Data'!A2:A288,A37,'Coverage Data'!G2:G288,"YES") -> 3 | D37: =B37-C37 -> 0 | E37: =IF(B37>0,C37/B37,0) -> 1
A38: Bldg E14 – Media Lab (new) | B38: =COUNTIF('Coverage Data'!A2:A288,A38) -> 7 | C38: =COUNTIFS('Coverage Data'!A2:A288,A38,'Coverage Data'!G2:G288,"YES") -> 6 | D38: =B38-C38 -> 1 | E38: =IF(B38>0,C38/B38,0) -> 0.85714286
A39: Bldg E15 – Wiesner (Media Arts) | B39: =COUNTIF('Coverage Data'!A2:A288,A39) -> 4 | C39: =COUNTIFS('Coverage Data'!A2:A288,A39,'Coverage Data'!G2:G288,"YES") -> 2 | D39: =B39-C39 -> 2 | E39: =IF(B39>0,C39/B39,0) -> 0.5
A40: Bldg E17 – MIT Admissions | B40: =COUNTIF('Coverage Data'!A2:A288,A40) -> 3 | C40: =COUNTIFS('Coverage Data'!A2:A288,A40,'Coverage Data'!G2:G288,"YES") -> 1 | D40: =B40-C40 -> 2 | E40: =IF(B40>0,C40/B40,0) -> 0.33333333
...
